Workbook

Sheet Assumptions
B1: THE SOAP MAKER — MODEL ASSUMPTIONS
B2: Blue cells = editable inputs | Yellow bg = key assumptions | Black text = formulas | Green text = cross-sheet links
B4: ❶ PRICING
B5: Premium Monthly Price | C5: 4.99 | D5: Source: Project Plan §10
B6: Premium Annual Price | C6: 39.99 | D6: Source: Project Plan §10 — "Save 33%" badge
B7: Annual Plan % of Premium Subscribers | C7: 0.3 | D7: Typical consumer SaaS mix; annual holders have lower churn
B8: Stripe Variable Fee | C8: 0.029 | D8: Source: stripe.com/pricing — standard card rate 2.9%
B9: Stripe Fixed Fee per Transaction | C9: 0.3 | D9: Source: stripe.com/pricing — $0.30/transaction
B11: ❷ AD REVENUE
B12: AdSense RPM (Revenue per 1,000 Impressions) | C12: 2.5 | D12: Hobby/DIY niche typical range $1.50–$4.00. Conservative at $2.50
B13: Page Views per User per Session | C13: 5 | D13: Landing → recipe list → 2 recipe details → profile
B14: Sessions per Free User per Month | C14: 3 | D14: Hobby app — not daily use; ~3 visits/mo realistic
B15: Ad Impressions per Page View | C15: 2 | D15: Avg of 3 slots (leaderboard, rectangle, in-feed) — not all on every page
B17: ❸ USER GROWTH & CONVERSION
B18: Free-to-Premium Conversion Rate (of new signups) | C18: 0.03 | D18: 7-day trial drives conversion; typical consumer SaaS range 2–5%
B19: Monthly Premium Subscriber Churn Rate | C19: 0.05 | D19: Typical hobby app churn ~5%/mo; annual holders churn less
B20: Active User Rate (% of registered, monthly) | C20: 0.7 | D20: 70% of registered users remain monthly active (hobby app estimate)
B22: ❹ INFRASTRUCTURE COSTS (MONTHLY)
B23: Startup Phase — Months 1–3 (all free tiers) | C23: 1 | D23: Domain only (~$1/mo). Vercel/Render/Cloudinary/DB all on free tiers
B24: Growth Phase — Months 4–24 | C24: 15 | D24: Render Web Service $7 + Render PostgreSQL $7 + Domain $1 = $15/mo
B25: Scale Phase — Months 25–36 | C25: 30 | D25: Growth tier + Render compute upgrade ~+$15 as traffic grows
B27: ❺ DERIVED VALUES (auto-calculated — do not edit)
B28: Net Revenue — Monthly Subscriber (after Stripe) | C28: =C5*(1-C8)-C9 -> 4.54529 | D28: Monthly price × (1−Stripe%) − fixed fee
B29: Net Revenue — Annual Subscriber (per month) | C29: =(C6*(1-C8)-C9)/12 -> 3.2108575 | D29: Annual price net of Stripe fees ÷ 12
B30: Blended Net Revenue per Premium User/mo | C30: =C28*(1-C7)+C29*C7 -> 4.1449602 | D30: 70% monthly × net monthly rev + 30% annual × net annual/mo
B31: Ad Revenue per Free Active User per Month | C31: =C13*C14*C15/1000*C12 -> 0.075 | D31: Pages/session × sessions/mo × impressions/page ÷ 1,000 × RPM

Sheet Cost Breakdown
B1: THE SOAP MAKER — INFRASTRUCTURE COST BREAKDOWN
B2: Monthly cost per service across three operational phases. Blue = inputs; totals are Excel formulas.
B4: Service | C4: Phase 1: Launch (Months 1–3) | D4: Phase 2: Growth (Months 4–24) | E4: Phase 3: Scale (Months 25–36) | F4: Notes
B5: Vercel (Frontend Hosting) | C5: 0 | D5: 0 | E5: 0 | F5: Free tier handles most traffic; Pro ($20/mo) only if hitting 100GB/mo bandwidth
B6: Render Web Service (Django/API) | C6: 0 | D6: 7 | E6: 7 | F6: Free tier spins down after 15 min; Starter ($7/mo) for always-on service
B7: Render PostgreSQL | C7: 0 | D7: 7 | E7: 7 | F7: Free tier: 90-day limit; Starter ($7/mo) for persistent DB. Budget from day 1
B8: Cloudinary (Media/Images) | C8: 0 | D8: 0 | E8: 0 | F8: Free tier: 25 GB storage + 25 GB BW/mo — sufficient through Year 3 easily
B9: Custom Domain (thesoapmaker.com) | C9: 1 | D9: 1 | E9: 1 | F9: ~$12/yr ≈ $1/mo via Namecheap or Cloudflare Registrar
B10: Transactional Email | C10: 0 | D10: 0 | E10: 0 | F10: SendGrid free tier: 100 emails/day — sufficient for auth/verification emails
B11: Google AdSense | C11: 0 | D11: 0 | E11: 0 | F11: Free to join; Google pays you — no monthly cost
B12: Stripe (Payments) | C12: 0 | D12: 0 | E12: 0 | F12: No monthly fee. 2.9% + $0.30 per transaction only
B13: Google Analytics 4 | C13: 0 | D13: 0 | E13: 0 | F13: Free
B14: GitHub (Repo + CI/CD) | C14: 0 | D14: 0 | E14: 0 | F14: Free for public repos; 2,000 Actions min/mo free on free plan
B15: Render Scale Upgrade | C15: 0 | D15: 0 | E15: 14 | F15: Additional compute when traffic grows beyond Starter; upgrade as needed
B16: TOTAL MONTHLY INFRASTRUCTURE COST | C16: =SUM(C5:C15) -> 1 | D16: =SUM(D5:D15) -> 15 | E16: =SUM(E5:E15) -> 29
B18: ⚠ Key Scaling Triggers — When to Upgrade
B19: • Render Free → Starter ($7/mo) | C19: At launch — eliminate the 15-min spin-down cold start from day one
B20: • Render DB Free → Paid ($7/mo) | C20: After 90 days when free DB expires; plan budget for this from the start
B21: • Vercel Free → Pro ($20/mo) | C21: Only needed at ~50,000+ MAU when exceeding 100 GB/mo bandwidth
B22: • Cloudinary Free → Paid ($89/mo) | C22: When image storage exceeds 25 GB — roughly 5,000+ image-rich recipes uploaded
B23: • Render Starter → Standard ($25/mo) | C23: When backend response times degrade under sustained load — monitor in GA4/Render dashboard

Sheet Break-Even Analysis
B1: THE SOAP MAKER — BREAK-EVEN ANALYSIS
B2: Three scenarios: (A) ad revenue only | (B) premium subscribers only | (C) blended model (realistic)
B4: Monthly Infrastructure Cost Reference (Growth Phase)
B5: Growth Phase Monthly Cost (Months 4–24) | C5: =Assumptions!C24 -> 15 | D5: Break-even target used in all scenarios below
B7: SCENARIO A — Break-Even with Ad Revenue Only (no premium subscribers)
B8: Monthly Cost Target | C8: =C5 -> 15 | D8: Break-even target from Growth Phase
B9: Ad Revenue per Free Active User/mo | C9: =Assumptions!C31 -> 0.075 | D9: Pulled from Assumptions (RPM × pages × sessions × impressions)
B10: Free Active Users Needed to Break Even | C10: =CEILING(C8/C9,1) -> 200 | D10: Monthly cost ÷ ad revenue per user
B11: Registered Users Needed (÷ 70% active rate) | C11: =CEILING(C10/Assumptions!C20,1) -> 286 | D11: Active users needed ÷ active rate
B12: Estimated Timeline | C12: Month 2–3 | D12: Growth model shows ~300 registered users by Month 2
B14: SCENARIO B — Break-Even with Premium Subscribers Only (no ads)
B15: Monthly Cost Target | C15: =C5 -> 15 | D15: Break-even target
B16: Blended Net Revenue per Premium User/mo | C16: =Assumptions!C30 -> 4.1449602 | D16: After Stripe fees; blended monthly/annual mix
B17: Premium Subscribers Needed to Break Even | C17: =CEILING(C15/C16,1) -> 4 | D17: Rounded up to whole subscribers
B18: Approx. Registered Users Required (at 3% conv.) | C18: =CEILING(C17/Assumptions!C18,1) -> 134 | D18: Premium needed ÷ conversion rate (rough proxy)
B19: Estimated Timeline | C19: Month 3–5 | D19: Model shows ~4–6 premium users within first 3 months
B21: SCENARIO C — Blended Model (realistic steady state)
B22: Monthly Cost Target | C22: =C5 -> 15 | D22: Break-even target
B23: Revenue Mix — % from Subscriptions | C23: 0.6 | D23: Editable assumption: 60% sub / 40% ad at maturity
B24: Revenue from Subscriptions Needed | C24: =C22*C23 -> 9 | D24: 60% of monthly infrastructure cost
B25: Revenue from Ads Needed | C25: =C22*(1-C23) -> 6 | D25: 40% of monthly infrastructure cost
B26: Premium Subscribers Required | C26: =CEILING(C24/Assumptions!C30,1) -> 3 | D26: Subscription revenue needed ÷ blended net per subscriber
B27: Free Active Users Required | C27: =CEILING(C25/Assumptions!C31,1) -> 80 | D27: Ad revenue needed ÷ ad revenue per free active user
B28: Total Active Users at Break-Even | C28: =C26+C27 -> 83 | D28: Sum: premium + free active
B30: 📊 BREAK-EVEN SUMMARY
B31: Scenario A — Ad Revenue Only | C31: ~200 free active users (~286 registered) needed
B32: Scenario B — Premium Subs Only | C32: Only 4 paying subscribers cover the $15/mo infra cost
B33: Scenario C — Blended 60/40 | C33: ~10 premium + ~80 free active (realistically Month 2–4)
B34: 💡 Key Insight | C34: Infrastructure costs are negligible ($1–$30/mo). This app becomes cash-flow positive very early. The growth opportunity — not cost control — is the main lever.

Sheet 3-Year Projection
B1: THE SOAP MAKER — 3-YEAR MONTHLY PROJECTION
B2: Blue = hardcoded input assumptions (editable) | Black = formulas | Green = cross-sheet links to Assumptions tab
B4: YEAR 1 (Months 1–12)
B5: Mo. | C5: Period | D5: New Signups | E5: Cum. Registered | F5: Active Users | G5: New Prem. Converts | H5: Premium Subs | I5: Free Active Users | J5: Ad Revenue ($) | K5: Sub Revenue ($) | L5: Total Revenue ($) | M5: Infra Cost ($) | N5: Net Profit ($) | O5: Cumul. P&L ($)
B6: 1 | C6: Jan Y1 | D6: 75 | E6: =D6 -> 75 | F6: =ROUND(E6*Assumptions!$C$20,0) -> 53 | G6: =ROUND(D6*Assumptions!$C$18,0) -> 2 | H6: =G6 -> 2 | I6: =MAX(0,F6-H6) -> 51 | J6: =ROUND(I6*Assumptions!$C$13*Assumptions!$C$14*Assumptions!$C$15/1000*Assumptions!$C$12,2) -> 3.83 | K6: =ROUND(H6*Assumptions!$C$30,2) -> 8.29 | L6: =J6+K6 -> 12.12 | M6: =IF(B6<=3,Assumptions!$C$23,IF(B6<=24,Assumptions!$C$24,Assumptions!$C$25)) -> 1 | N6: =L6-M6 -> 11.12 | O6: =N6 -> 11.12
B7: 2 | C7: Feb Y1 | D7: 115 | E7: =E6+D7 -> 190 | F7: =ROUND(E7*Assumptions!$C$20,0) -> 133 | G7: =ROUND(D7*Assumptions!$C$18,0) -> 3 | H7: =MAX(0,ROUND(H6*(1-Assumptions!$C$19)+G7,0)) -> 5 | I7: =MAX(0,F7-H7) -> 128 | J7: =ROUND(I7*Assumptions!$C$13*Assumptions!$C$14*Assumptions!$C$15/1000*Assumptions!$C$12,2) -> 9.6 | K7: =ROUND(H7*Assumptions!$C$30,2) -> 20.72 | L7: =J7+K7 -> 30.32 | M7: =IF(B7<=3,Assumptions!$C$23,IF(B7<=24,Assumptions!$C$24,Assumptions!$C$25)) -> 1 | N7: =L7-M7 -> 29.32 | O7: =O6+N7 -> 40.44
B8: 3 | C8: Mar Y1 | D8: 160 | E8: =E7+D8 -> 350 | F8: =ROUND(E8*Assumptions!$C$20,0) -> 245 | G8: =ROUND(D8*Assumptions!$C$18,0) -> 5 | H8: =MAX(0,ROUND(H7*(1-Assumptions!$C$19)+G8,0)) -> 10 | I8: =MAX(0,F8-H8) -> 235 | J8: =ROUND(I8*Assumptions!$C$13*Assumptions!$C$14*Assumptions!$C$15/1000*Assumptions!$C$12,2) -> 17.63 | K8: =ROUND(H8*Assumptions!$C$30,2) -> 41.45 | L8: =J8+K8 -> 59.08 | M8: =IF(B8<=3,Assumptions!$C$23,IF(B8<=24,Assumptions!$C$24,Assumptions!$C$25)) -> 1 | N8: =L8-M8 -> 58.08 | O8: =O7+N8 -> 98.52
B9: 4 | C9: Apr Y1 | D9: 205 | E9: =E8+D9 -> 555 | F9: =ROUND(E9*Assumptions!$C$20,0) -> 389 | G9: =ROUND(D9*Assumptions!$C$18,0) -> 6 | H9: =MAX(0,ROUND(H8*(1-Assumptions!$C$19)+G9,0)) -> 16 | I9: =MAX(0,F9-H9) -> 373 | J9: =ROUND(I9*Assumptions!$C$13*Assumptions!$C$14*Assumptions!$C$15/1000*Assumptions!$C$12,2) -> 27.98 | K9: =ROUND(H9*Assumptions!$C$30,2) -> 66.32 | L9: =J9+K9 -> 94.3 | M9: =IF(B9<=3,Assumptions!$C$23,IF(B9<=24,Assumptions!$C$24,Assumptions!$C$25)) -> 15 | N9: =L9-M9 -> 79.3 | O9: =O8+N9 -> 177.82
B10: 5 | C10: May Y1 | D10: 245 | E10: =E9+D10 -> 800 | F10: =ROUND(E10*Assumptions!$C$20,0) -> 560 | G10: =ROUND(D10*Assumptions!$C$18,0) -> 7 | H10: =MAX(0,ROUND(H9*(1-Assumptions!$C$19)+G10,0)) -> 22 | I10: =MAX(0,F10-H10) -> 538 | J10: =ROUND(I10*Assumptions!$C$13*Assumptions!$C$14*Assumptions!$C$15/1000*Assumptions!$C$12,2) -> 40.35 | K10: =ROUND(H10*Assumptions!$C$30,2) -> 91.19 | L10: =J10+K10 -> 131.54 | M10: =IF(B10<=3,Assumptions!$C$23,IF(B10<=24,Assumptions!$C$24,Assumptions!$C$25)) -> 15 | N10: =L10-M10 -> 116.54 | O10: =O9+N10 -> 294.36
B11: 6 | C11: Jun Y1 | D11: 285 | E11: =E10+D11 -> 1085 | F11: =ROUND(E11*Assumptions!$C$20,0) -> 760 | G11: =ROUND(D11*Assumptions!$C$18,0) -> 9 | H11: =MAX(0,ROUND(H10*(1-Assumptions!$C$19)+G11,0)) -> 30 | I11: =MAX(0,F11-H11) -> 730 | J11: =ROUND(I11*Assumptions!$C$13*Assumptions!$C$14*Assumptions!$C$15/1000*Assumptions!$C$12,2) -> 54.75 | K11: =ROUND(H11*Assumptions!$C$30,2) -> 124.35 | L11: =J11+K11 -> 179.1 | M11: =IF(B11<=3,Assumptions!$C$23,IF(B11<=24,Assumptions!$C$24,Assumptions!$C$25)) -> 15 | N11: =L11-M11 -> 164.1 | O11: =O10+N11 -> 458.46
B12: 7 | C12: Jul Y1 | D12: 315 | E12: =E11+D12 -> 1400 | F12: =ROUND(E12*Assumptions!$C$20,0) -> 980 | G12: =ROUND(D12*Assumptions!$C$18,0) -> 9 | H12: =MAX(0,ROUND(H11*(1-Assumptions!$C$19)+G12,0)) -> 38 | I12: =MAX(0,F12-H12) -> 942 | J12: =ROUND(I12*Assumptions!$C$13*Assumptions!$C$14*Assumptions!$C$15/1000*Assumptions!$C$12,2) -> 70.65 | K12: =ROUND(H12*Assumptions!$C$30,2) -> 157.51 | L12: =J12+K12 -> 228.16 | M12: =IF(B12<=3,Assumptions!$C$23,IF(B12<=24,Assumptions!$C$24,Assumptions!$C$25)) -> 15 | N12: =L12-M12 -> 213.16 | O12: =O11+N12 -> 671.62
B13: 8 | C13: Aug Y1 | D13: 340 | E13: =E12+D13 -> 1740 | F13: =ROUND(E13*Assumptions!$C$20,0) -> 1218 | G13: =ROUND(D13*Assumptions!$C$18,0) -> 10 | H13: =MAX(0,ROUND(H12*(1-Assumptions!$C$19)+G13,0)) -> 46 | I13: =MAX(0,F13-H13) -> 1172 | J13: =ROUND(I13*Assumptions!$C$13*Assumptions!$C$14*Assumptions!$C$15/1000*Assumptions!$C$12,2) -> 87.9 | K13: =ROUND(H13*Assumptions!$C$30,2) -> 190.67 | L13: =J13+K13 -> 278.57 | M13: =IF(B13<=3,Assumptions!$C$23,IF(B13<=24,Assumptions!$C$24,Assumptions!$C$25)) -> 15 | N13: =L13-M13 -> 263.57 | O13: =O12+N13 -> 935.19
B14: 9 | C14: Sep Y1 | D14: 360 | E14: =E13+D14 -> 2100 | F14: =ROUND(E14*Assumptions!$C$20,0) -> 1470 | G14: =ROUND(D14*Assumptions!$C$18,0) -> 11 | H14: =MAX(0,ROUND(H13*(1-Assumptions!$C$19)+G14,0)) -> 55 | I14: =MAX(0,F14-H14) -> 1415 | J14: =ROUND(I14*Assumptions!$C$13*Assumptions!$C$14*Assumptions!$C$15/1000*Assumptions!$C$12,2) -> 106.13 | K14: =ROUND(H14*Assumptions!$C$30,2) -> 227.97 | L14: =J14+K14 -> 334.1 | M14: =IF(B14<=3,Assumptions!$C$23,IF(B14<=24,Assumptions!$C$24,Assumptions!$C$25)) -> 15 | N14: =L14-M14 -> 319.1 | O14: =O13+N14 -> 1254.29
B15: 10 | C15: Oct Y1 | D15: 375 | E15: =E14+D15 -> 2475 | F15: =ROUND(E15*Assumptions!$C$20,0) -> 1733 | G15: =ROUND(D15*Assumptions!$C$18,0) -> 11 | H15: =MAX(0,ROUND(H14*(1-Assumptions!$C$19)+G15,0)) -> 63 | I15: =MAX(0,F15-H15) -> 1670 | J15: =ROUND(I15*Assumptions!$C$13*Assumptions!$C$14*Assumptions!$C$15/1000*Assumptions!$C$12,2) -> 125.25 | K15: =ROUND(H15*Assumptions!$C$30,2) -> 261.13 | L15: =J15+K15 -> 386.38 | M15: =IF(B15<=3,Assumptions!$C$23,IF(B15<=24,Assumptions!$C$24,Assumptions!$C$25)) -> 15 | N15: =L15-M15 -> 371.38 | O15: =O14+N15 -> 1625.67
B16: 11 | C16: Nov Y1 | D16: 385 | E16: =E15+D16 -> 2860 | F16: =ROUND(E16*Assumptions!$C$20,0) -> 2002 | G16: =ROUND(D16*Assumptions!$C$18,0) -> 12 | H16: =MAX(0,ROUND(H15*(1-Assumptions!$C$19)+G16,0)) -> 72 | I16: =MAX(0,F16-H16) -> 1930 | J16: =ROUND(I16*Assumptions!$C$13*Assumptions!$C$14*Assumptions!$C$15/1000*Assumptions!$C$12,2) -> 144.75 | K16: =ROUND(H16*Assumptions!$C$30,2) -> 298.44 | L16: =J16+K16 -> 443.19 | M16: =IF(B16<=3,Assumptions!$C$23,IF(B16<=24,Assumptions!$C$24,Assumptions!$C$25)) -> 15 | N16: =L16-M16 -> 428.19 | O16: =O15+N16 -> 2053.86
B17: 12 | C17: Dec Y1 | D17: 392 | E17: =E16+D17 -> 3252 | F17: =ROUND(E17*Assumptions!$C$20,0) -> 2276 | G17: =ROUND(D17*Assumptions!$C$18,0) -> 12 | H17: =MAX(0,ROUND(H16*(1-Assumptions!$C$19)+G17,0)) -> 80 | I17: =MAX(0,F17-H17) -> 2196 | J17: =ROUND(I17*Assumptions!$C$13*Assumptions!$C$14*Assumptions!$C$15/1000*Assumptions!$C$12,2) -> 164.7 | K17: =ROUND(H17*Assumptions!$C$30,2) -> 331.6 | L17: =J17+K17 -> 496.3 | M17: =IF(B17<=3,Assumptions!$C$23,IF(B17<=24,Assumptions!$C$24,Assumptions!$C$25)) -> 15 | N17: =L17-M17 -> 481.3 | O17: =O16+N17 -> 2535.16
B18: YEAR 2 (Months 13–24)
B19: Mo. | C19: Period | D19: New Signups | E19: Cum. Registered | F19: Active Users | G19: New Prem. Converts | H19: Premium Subs | I19: Free Active Users | J19: Ad Revenue ($) | K19: Sub Revenue ($) | L19: Total Revenue ($) | M19: Infra Cost ($) | N19: Net Profit ($) | O19: Cumul. P&L ($)
B20: 13 | C20: Jan Y2 | D20: 400 | E20: =E17+D20 -> 3652 | F20: =ROUND(E20*Assumptions!$C$20,0) -> 2556 | G20: =ROUND(D20*Assumptions!$C$18,0) -> 12 | H20: =MAX(0,ROUND(H17*(1-Assumptions!$C$19)+G20,0)) -> 88 | I20: =MAX(0,F20-H20) -> 2468 | J20: =ROUND(I20*Assumptions!$C$13*Assumptions!$C$14*Assumptions!$C$15/1000*Assumptions!$C$12,2) -> 185.1 | K20: =ROUND(H20*Assumptions!$C$30,2) -> 364.76 | L20: =J20+K20 -> 549.86 | M20: =IF(B20<=3,Assumptions!$C$23,IF(B20<=24,Assumptions!$C$24,Assumptions!$C$25)) -> 15 | N20: =L20-M20 -> 534.86 | O20: =O17+N20 -> 3070.02
B21: 14 | C21: Feb Y2 | D21: 415 | E21: =E20+D21 -> 4067 | F21: =ROUND(E21*Assumptions!$C$20,0) -> 2847 | G21: =ROUND(D21*Assumptions!$C$18,0) -> 12 | H21: =MAX(0,ROUND(H20*(1-Assumptions!$C$19)+G21,0)) -> 96 | I21: =MAX(0,F21-H21) -> 2751 | J21: =ROUND(I21*Assumptions!$C$13*Assumptions!$C$14*Assumptions!$C$15/1000*Assumptions!$C$12,2) -> 206.33 | K21: =ROUND(H21*Assumptions!$C$30,2) -> 397.92 | L21: =J21+K21 -> 604.25 | M21: =IF(B21<=3,Assumptions!$C$23,IF(B21<=24,Assumptions!$C$24,Assumptions!$C$25)) -> 15 | N21: =L21-M21 -> 589.25 | O21: =O20+N21 -> 3659.27
B22: 15 | C22: Mar Y2 | D22: 430 | E22: =E21+D22 -> 4497 | F22: =ROUND(E22*Assumptions!$C$20,0) -> 3148 | G22: =ROUND(D22*Assumptions!$C$18,0) -> 13 | H22: =MAX(0,ROUND(H21*(1-Assumptions!$C$19)+G22,0)) -> 104 | I22: =MAX(0,F22-H22) -> 3044 | J22: =ROUND(I22*Assumptions!$C$13*Assumptions!$C$14*Assumptions!$C$15/1000*Assumptions!$C$12,2) -> 228.3 | K22: =ROUND(H22*Assumptions!$C$30,2) -> 431.08 | L22: =J22+K22 -> 659.38 | M22: =IF(B22<=3,Assumptions!$C$23,IF(B22<=24,Assumptions!$C$24,Assumptions!$C$25)) -> 15 | N22: =L22-M22 -> 644.38 | O22: =O21+N22 -> 4303.65
B23: 16 | C23: Apr Y2 | D23: 445 | E23: =E22+D23 -> 4942 | F23: =ROUND(E23*Assumptions!$C$20,0) -> 3459 | G23: =ROUND(D23*Assumptions!$C$18,0) -> 13 | H23: =MAX(0,ROUND(H22*(1-Assumptions!$C$19)+G23,0)) -> 112 | I23: =MAX(0,F23-H23) -> 3347 | J23: =ROUND(I23*Assumptions!$C$13*Assumptions!$C$14*Assumptions!$C$15/1000*Assumptions!$C$12,2) -> 251.03 | K23: =ROUND(H23*Assumptions!$C$30,2) -> 464.24 | L23: =J23+K23 -> 715.27 | M23: =IF(B23<=3,Assumptions!$C$23,IF(B23<=24,Assumptions!$C$24,Assumptions!$C$25)) -> 15 | N23: =L23-M23 -> 700.27 | O23: =O22+N23 -> 5003.92
B24: 17 | C24: May Y2 | D24: 460 | E24: =E23+D24 -> 5402 | F24: =ROUND(E24*Assumptions!$C$20,0) -> 3781 | G24: =ROUND(D24*Assumptions!$C$18,0) -> 14 | H24: =MAX(0,ROUND(H23*(1-Assumptions!$C$19)+G24,0)) -> 120 | I24: =MAX(0,F24-H24) -> 3661 | J24: =ROUND(I24*Assumptions!$C$13*Assumptions!$C$14*Assumptions!$C$15/1000*Assumptions!$C$12,2) -> 274.58 | K24: =ROUND(H24*Assumptions!$C$30,2) -> 497.4 | L24: =J24+K24 -> 771.98 | M24: =IF(B24<=3,Assumptions!$C$23,IF(B24<=24,Assumptions!$C$24,Assumptions!$C$25)) -> 15 | N24: =L24-M24 -> 756.98 | O24: =O23+N24 -> 5760.9
B25: 18 | C25: Jun Y2 | D25: 475 | E25: =E24+D25 -> 5877 | F25: =ROUND(E25*Assumptions!$C$20,0) -> 4114 | G25: =ROUND(D25*Assumptions!$C$18,0) -> 14 | H25: =MAX(0,ROUND(H24*(1-Assumptions!$C$19)+G25,0)) -> 128 | I25: =MAX(0,F25-H25) -> 3986 | J25: =ROUND(I25*Assumptions!$C$13*Assumptions!$C$14*Assumptions!$C$15/1000*Assumptions!$C$12,2) -> 298.95 | K25: =ROUND(H25*Assumptions!$C$30,2) -> 530.55 | L25: =J25+K25 -> 829.5 | M25: =IF(B25<=3,Assumptions!$C$23,IF(B25<=24,Assumptions!$C$24,Assumptions!$C$25)) -> 15 | N25: =L25-M25 -> 814.5 | O25: =O24+N25 -> 6575.4
B26: 19 | C26: Jul Y2 | D26: 495 | E26: =E25+D26 -> 6372 | F26: =ROUND(E26*Assumptions!$C$20,0) -> 4460 | G26: =ROUND(D26*Assumptions!$C$18,0) -> 15 | H26: =MAX(0,ROUND(H25*(1-Assumptions!$C$19)+G26,0)) -> 137 | I26: =MAX(0,F26-H26) -> 4323 | J26: =ROUND(I26*Assumptions!$C$13*Assumptions!$C$14*Assumptions!$C$15/1000*Assumptions!$C$12,2) -> 324.23 | K26: =ROUND(H26*Assumptions!$C$30,2) -> 567.86 | L26: =J26+K26 -> 892.09 | M26: =IF(B26<=3,Assumptions!$C$23,IF(B26<=24,Assumptions!$C$24,Assumptions!$C$25)) -> 15 | N26: =L26-M26 -> 877.09 | O26: =O25+N26 -> 7452.49
B27: 20 | C27: Aug Y2 | D27: 515 | E27: =E26+D27 -> 6887 | F27: =ROUND(E27*Assumptions!$C$20,0) -> 4821 | G27: =ROUND(D27*Assumptions!$C$18,0) -> 15 | H27: =MAX(0,ROUND(H26*(1-Assumptions!$C$19)+G27,0)) -> 145 | I27: =MAX(0,F27-H27) -> 4676 | J27: =ROUND(I27*Assumptions!$C$13*Assumptions!$C$14*Assumptions!$C$15/1000*Assumptions!$C$12,2) -> 350.7 | K27: =ROUND(H27*Assumptions!$C$30,2) -> 601.02 | L27: =J27+K27 -> 951.72 | M27: =IF(B27<=3,Assumptions!$C$23,IF(B27<=24,Assumptions!$C$24,Assumptions!$C$25)) -> 15 | N27: =L27-M27 -> 936.72 | O27: =O26+N27 -> 8389.21
B28: 21 | C28: Sep Y2 | D28: 535 | E28: =E27+D28 -> 7422 | F28: =ROUND(E28*Assumptions!$C$20,0) -> 5195 | G28: =ROUND(D28*Assumptions!$C$18,0) -> 16 | H28: =MAX(0,ROUND(H27*(1-Assumptions!$C$19)+G28,0)) -> 154 | I28: =MAX(0,F28-H28) -> 5041 | J28: =ROUND(I28*Assumptions!$C$13*Assumptions!$C$14*Assumptions!$C$15/1000*Assumptions!$C$12,2) -> 378.08 | K28: =ROUND(H28*Assumptions!$C$30,2) -> 638.32 | L28: =J28+K28 -> 1016.4 | M28: =IF(B28<=3,Assumptions!$C$23,IF(B28<=24,Assumptions!$C$24,Assumptions!$C$25)) -> 15 | N28: =L28-M28 -> 1001.4 | O28: =O27+N28 -> 9390.61
B29: 22 | C29: Oct Y2 | D29: 560 | E29: =E28+D29 -> 7982 | F29: =ROUND(E29*Assumptions!$C$20,0) -> 5587 | G29: =ROUND(D29*Assumptions!$C$18,0) -> 17 | H29: =MAX(0,ROUND(H28*(1-Assumptions!$C$19)+G29,0)) -> 163 | I29: =MAX(0,F29-H29) -> 5424 | J29: =ROUND(I29*Assumptions!$C$13*Assumptions!$C$14*Assumptions!$C$15/1000*Assumptions!$C$12,2) -> 406.8 | K29: =ROUND(H29*Assumptions!$C$30,2) -> 675.63 | L29: =J29+K29 -> 1082.43 | M29: =IF(B29<=3,Assumptions!$C$23,IF(B29<=24,Assumptions!$C$24,Assumptions!$C$25)) -> 15 | N29: =L29-M29 -> 1067.43 | O29: =O28+N29 -> 10458.04
B30: 23 | C30: Nov Y2 | D30: 585 | E30: =E29+D30 -> 8567 | F30: =ROUND(E30*Assumptions!$C$20,0) -> 5997 | G30: =ROUND(D30*Assumptions!$C$18,0) -> 18 | H30: =MAX(0,ROUND(H29*(1-Assumptions!$C$19)+G30,0)) -> 173 | I30: =MAX(0,F30-H30) -> 5824 | J30: =ROUND(I30*Assumptions!$C$13*Assumptions!$C$14*Assumptions!$C$15/1000*Assumptions!$C$12,2) -> 436.8 | K30: =ROUND(H30*Assumptions!$C$30,2) -> 717.08 | L30: =J30+K30 -> 1153.88 | M30: =IF(B30<=3,Assumptions!$C$23,IF(B30<=24,Assumptions!$C$24,Assumptions!$C$25)) -> 15 | N30: =L30-M30 -> 1138.88 | O30: =O29+N30 -> 11596.92
B31: 24 | C31: Dec Y2 | D31: 615 | E31: =E30+D31 -> 9182 | F31: =ROUND(E31*Assumptions!$C$20,0) -> 6427 | G31: =ROUND(D31*Assumptions!$C$18,0) -> 18 | H31: =MAX(0,ROUND(H30*(1-Assumptions!$C$19)+G31,0)) -> 182 | I31: =MAX(0,F31-H31) -> 6245 | J31: =ROUND(I31*Assumptions!$C$13*Assumptions!$C$14*Assumptions!$C$15/1000*Assumptions!$C$12,2) -> 468.38 | K31: =ROUND(H31*Assumptions!$C$30,2) -> 754.38 | L31: =J31+K31 -> 1222.76 | M31: =IF(B31<=3,Assumptions!$C$23,IF(B31<=24,Assumptions!$C$24,Assumptions!$C$25)) -> 15 | N31: =L31-M31 -> 1207.76 | O31: =O30+N31 -> 12804.68
B32: YEAR 3 (Months 25–36)
B33: Mo. | C33: Period | D33: New Signups | E33: Cum. Registered | F33: Active Users | G33: New Prem. Converts | H33: Premium Subs | I33: Free Active Users | J33: Ad Revenue ($) | K33: Sub Revenue ($) | L33: Total Revenue ($) | M33: Infra Cost ($) | N33: Net Profit ($) | O33: Cumul. P&L ($)
B34: 25 | C34: Jan Y3 | D34: 645 | E34: =E31+D34 -> 9827 | F34: =ROUND(E34*Assumptions!$C$20,0) -> 6879 | G34: =ROUND(D34*Assumptions!$C$18,0) -> 19 | H34: =MAX(0,ROUND(H31*(1-Assumptions!$C$19)+G34,0)) -> 192 | I34: =MAX(0,F34-H34) -> 6687 | J34: =ROUND(I34*Assumptions!$C$13*Assumptions!$C$14*Assumptions!$C$15/1000*Assumptions!$C$12,2) -> 501.53 | K34: =ROUND(H34*Assumptions!$C$30,2) -> 795.83 | L34: =J34+K34 -> 1297.36 | M34: =IF(B34<=3,Assumptions!$C$23,IF(B34<=24,Assumptions!$C$24,Assumptions!$C$25)) -> 30 | N34: =L34-M34 -> 1267.36 | O34: =O31+N34 -> 14072.04
B35: 26 | C35: Feb Y3 | D35: 680 | E35: =E34+D35 -> 10507 | F35: =ROUND(E35*Assumptions!$C$20,0) -> 7355 | G35: =ROUND(D35*Assumptions!$C$18,0) -> 20 | H35: =MAX(0,ROUND(H34*(1-Assumptions!$C$19)+G35,0)) -> 202 | I35: =MAX(0,F35-H35) -> 7153 | J35: =ROUND(I35*Assumptions!$C$13*Assumptions!$C$14*Assumptions!$C$15/1000*Assumptions!$C$12,2) -> 536.48 | K35: =ROUND(H35*Assumptions!$C$30,2) -> 837.28 | L35: =J35+K35 -> 1373.76 | M35: =IF(B35<=3,Assumptions!$C$23,IF(B35<=24,Assumptions!$C$24,Assumptions!$C$25)) -> 30 | N35: =L35-M35 -> 1343.76 | O35: =O34+N35 -> 15415.8
B36: 27 | C36: Mar Y3 | D36: 715 | E36: =E35+D36 -> 11222 | F36: =ROUND(E36*Assumptions!$C$20,0) -> 7855 | G36: =ROUND(D36*Assumptions!$C$18,0) -> 21 | H36: =MAX(0,ROUND(H35*(1-Assumptions!$C$19)+G36,0)) -> 213 | I36: =MAX(0,F36-H36) -> 7642 | J36: =ROUND(I36*Assumptions!$C$13*Assumptions!$C$14*Assumptions!$C$15/1000*Assumptions!$C$12,2) -> 573.15 | K36: =ROUND(H36*Assumptions!$C$30,2) -> 882.88 | L36: =J36+K36 -> 1456.03 | M36: =IF(B36<=3,Assumptions!$C$23,IF(B36<=24,Assumptions!$C$24,Assumptions!$C$25)) -> 30 | N36: =L36-M36 -> 1426.03 | O36: =O35+N36 -> 16841.83
B37: 28 | C37: Apr Y3 | D37: 750 | E37: =E36+D37 -> 11972 | F37: =ROUND(E37*Assumptions!$C$20,0) -> 8380 | G37: =ROUND(D37*Assumptions!$C$18,0) -> 23 | H37: =MAX(0,ROUND(H36*(1-Assumptions!$C$19)+G37,0)) -> 225 | I37: =MAX(0,F37-H37) -> 8155 | J37: =ROUND(I37*Assumptions!$C$13*Assumptions!$C$14*Assumptions!$C$15/1000*Assumptions!$C$12,2) -> 611.63 | K37: =ROUND(H37*Assumptions!$C$30,2) -> 932.62 | L37: =J37+K37 -> 1544.25 | M37: =IF(B37<=3,Assumptions!$C$23,IF(B37<=24,Assumptions!$C$24,Assumptions!$C$25)) -> 30 | N37: =L37-M37 -> 1514.25 | O37: =O36+N37 -> 18356.08
B38: 29 | C38: May Y3 | D38: 785 | E38: =E37+D38 -> 12757 | F38: =ROUND(E38*Assumptions!$C$20,0) -> 8930 | G38: =ROUND(D38*Assumptions!$C$18,0) -> 24 | H38: =MAX(0,ROUND(H37*(1-Assumptions!$C$19)+G38,0)) -> 238 | I38: =MAX(0,F38-H38) -> 8692 | J38: =ROUND(I38*Assumptions!$C$13*Assumptions!$C$14*Assumptions!$C$15/1000*Assumptions!$C$12,2) -> 651.9 | K38: =ROUND(H38*Assumptions!$C$30,2) -> 986.5 | L38: =J38+K38 -> 1638.4 | M38: =IF(B38<=3,Assumptions!$C$23,IF(B38<=24,Assumptions!$C$24,Assumptions!$C$25)) -> 30 | N38: =L38-M38 -> 1608.4 | O38: =O37+N38 -> 19964.48
B39: 30 | C39: Jun Y3 | D39: 825 | E39: =E38+D39 -> 13582 | F39: =ROUND(E39*Assumptions!$C$20,0) -> 9507 | G39: =ROUND(D39*Assumptions!$C$18,0) -> 25 | H39: =MAX(0,ROUND(H38*(1-Assumptions!$C$19)+G39,0)) -> 251 | I39: =MAX(0,F39-H39) -> 9256 | J39: =ROUND(I39*Assumptions!$C$13*Assumptions!$C$14*Assumptions!$C$15/1000*Assumptions!$C$12,2) -> 694.2 | K39: =ROUND(H39*Assumptions!$C$30,2) -> 1040.39 | L39: =J39+K39 -> 1734.59 | M39: =IF(B39<=3,Assumptions!$C$23,IF(B39<=24,Assumptions!$C$24,Assumptions!$C$25)) -> 30 | N39: =L39-M39 -> 1704.59 | O39: =O38+N39 -> 21669.07
B40: 31 | C40: Jul Y3 | D40: 865 | E40: =E39+D40 -> 14447 | F40: =ROUND(E40*Assumptions!$C$20,0) -> 10113 | G40: =ROUND(D40*Assumptions!$C$18,0) -> 26 | H40: =MAX(0,ROUND(H39*(1-Assumptions!$C$19)+G40,0)) -> 264 | I40: =MAX(0,F40-H40) -> 9849 | J40: =ROUND(I40*Assumptions!$C$13*Assumptions!$C$14*Assumptions!$C$15/1000*Assumptions!$C$12,2) -> 738.68 | K40: =ROUND(H40*Assumptions!$C$30,2) -> 1094.27 | L40: =J40+K40 -> 1832.95 | M40: =IF(B40<=3,Assumptions!$C$23,IF(B40<=24,Assumptions!$C$24,Assumptions!$C$25)) -> 30 | N40: =L40-M40 -> 1802.95 | O40: =O39+N40 -> 23472.02
B41: 32 | C41: Aug Y3 | D41: 905 | E41: =E40+D41 -> 15352 | F41: =ROUND(E41*Assumptions!$C$20,0) -> 10746 | G41: =ROUND(D41*Assumptions!$C$18,0) -> 27 | H41: =MAX(0,ROUND(H40*(1-Assumptions!$C$19)+G41,0)) -> 278 | I41: =MAX(0,F41-H41) -> 10468 | J41: =ROUND(I41*Assumptions!$C$13*Assumptions!$C$14*Assumptions!$C$15/1000*Assumptions!$C$12,2) -> 785.1 | K41: =ROUND(H41*Assumptions!$C$30,2) -> 1152.3 | L41: =J41+K41 -> 1937.4 | M41: =IF(B41<=3,Assumptions!$C$23,IF(B41<=24,Assumptions!$C$24,Assumptions!$C$25)) -> 30 | N41: =L41-M41 -> 1907.4 | O41: =O40+N41 -> 25379.42
...

Sheet Pricing Strategy
B1: THE SOAP MAKER — PRICING STRATEGY & RECOMMENDATIONS
B3: CURRENT PRICING MODEL
B4: Feature | C4: Free Tier | D4: Monthly ($4.99/mo) | E4: Annual ($39.99/yr) | F4: Analysis
B5: Browse all recipes | C5: ✓ | D5: ✓ | E5: ✓ | F5: Core feature — must stay free for SEO & discovery
B6: Submit & rate recipes | C6: ✓ | D6: ✓ | E6: ✓ | F6: Community contribution drives the content flywheel
B7: Ads displayed | C7: ✓ | D7: ✗ | E7: ✗ | F7: Ad-free is a strong, tangible premium incentive
B8: Lye Calculator | C8: ✗ | D8: ✓ | E8: ✓ | F8: High-value tool for serious crafters — key conversion driver
B9: Recipe Bookmarks | C9: ✗ | D9: ✓ | E9: ✓ | F9: Convenience feature; medium value
B10: Advanced Filters | C10: ✗ | D10: ✓ | E10: ✓ | F10: Power user feature
B11: Early Feature Access | C11: ✗ | D11: ✓ | E11: ✓ | F11: Community status incentive
B14: PRICING RECOMMENDATIONS
B15: ✅ Keep $4.99/mo Monthly Plan | C15: Competitive for a hobby/niche app. Low enough for impulse purchase, high enough to signal quality. Compare: Canva $6.99, Notion $8, MyFitnessPal $9.99.
B16: ✅ Keep $39.99/yr Annual Plan | C16: The ~33% discount (vs $59.88/yr at monthly rate) is a proven SaaS conversion lever. Annual subscribers have ~3× better LTV and lower churn than monthly.
B17: ✅ Keep 7-Day Free Trial (No Credit Card) | C17: No-CC-required trials increase trial sign-up rates dramatically (3–5× vs CC-required). Lower friction = more users experiencing premium value. Expect ~20–35% trial-to-paid conversion.
B18: 🔄 Add a Lifetime Plan at $79–$99 (at ~6 months post-launch) | C18: One-time payment appeals strongly to hobbyist audiences who dislike subscriptions. Can spike launch revenue, fund operations, and build a loyal base.
B19: 🔄 Consider a "Crafter Pro" Tier at $9.99/mo (Year 2+) | C19: Future tier adding: recipe PDF export, batch-size scaling calculator, household sharing (2 users), and API access for recipe app builders. Target power users.
B20: ⚠ Never Show Ads to Premium Users | C20: The primary premium value proposition is an ad-free experience. Any ads on premium pages would destroy trust and spike churn. Guard this line strictly.
B21: 📊 Primary Metric: Trial-to-Paid Conversion | C21: Target ≥25%. If consistently below 20%, the premium feature set is not compelling enough — add value before raising prices. Track weekly in GA4.
